<?xml version="1.0"?>
<robot name="headv1">

<material name="blue">
    <color rgba="0 0 0.8 1"/>
  </material>
  <material name="black">
    <color rgba="0 0 0 1"/>
  </material>
  <material name="white">
    <color rgba="1 1 1 1"/>
  </material>

  <link name="base">
    <visual>
      <origin
        xyz="0 0 0"
        rpy="0 0 0" />
      <geometry>
        <mesh filename="package://headv1/meshes/base.dae" />
      </geometry>
      <material name="black"/>
    </visual>
  </link>
  
  <link name="mid">
    <visual>
      <origin xyz="0 -0.005 0.06" rpy="0 0 0" />
      <geometry>
        <mesh filename="package://headv1/meshes/mid.dae" />
      </geometry>
      <material name="white"/>
    </visual>
  </link>
  
  <joint name="base_to_mid" type="revolute">
    <origin
      xyz="0 0.06678 0"
      rpy="0 0 0" />
    <parent link="base" />
    <child link="mid" />
    <axis xyz="0 1 0" />
    <limit
      lower="-3.14"
      upper="3.14"
      effort="1"
      velocity="3.14" />
  </joint>
  
  <link name="servo">
    <visual>
      <origin
        xyz="0.02 0.03 0.1"
        rpy="1.57075 0 -1.57075" />
      <geometry>
        <mesh filename="package://headv1/meshes/servo.dae" />
      </geometry>
      <material name="blue"/>
    </visual>
  </link>
  
  <joint name="mid_to_servo" type="revolute">
    <origin
      xyz="0.019723 0.0381 -0.0023295"
      rpy="0 0 0" />
    <parent link="mid" />
    <child link="servo" />
    <axis xyz="0.9931 0 -0.11729" />
    <limit
      lower="-1"
      upper="2"
      effort="1"
      velocity="3.14" />
    <dynamics
      friction="1" />
  </joint>
  
  <link name="kinect">
    <visual>
      <origin
        xyz="0 -0.05 0.12"
        rpy="1.57075 0 0" />
      <geometry>
        <box size="0.08 0.08 0.08"/>
        <mesh filename="package://headv1/meshes/kinect.dae" />
      </geometry>
      <material name="black"/>
    </visual>
  </link>
  
  <joint name="servo_to_kinect" type="revolute">
    <origin
      xyz="-0.011055 0.028845 0.050732"
      rpy="0 0 0" />
    <parent link="servo" />
    <child link="kinect" />
    <axis xyz="0.11729 0.0069852 0.99307" />
    <limit
      lower="-1.57"
      upper="1.57"
      effort="1"
      velocity="3.14" />
    <dynamics friction="1" />
  </joint>
 
</robot>
